<?xml version="1.0" ?>
<!-- =================================================================================== -->
<!-- |    This document was autogenerated by xacro from robot_seldat_1wheel_2.xacro    | -->
<!-- |    EDITING THIS FILE BY HAND IS NOT RECOMMENDED                                 | -->
<!-- =================================================================================== -->
<robot name="robot_seldat" xmlns:controller="http://playerstage.sourceforge.net/gazebo/xmlschema/#controller" xmlns:interface="http://playerstage.sourceforge.net/gazebo/xmlschema/#interface" xmlns:sensor="http://playerstage.sourceforge.net/gazebo/xmlschema/#sensor" xmlns:xacro="http://www.ros.org/wiki/xacro">
  <!--0.15-->
  <!--0.09-->
  <!--base footprint-->
  <!--	<link name="base_footprint">
   		<visual>
			<geometry>
      				<box size="0.001 0.001 0.001"/>
     			</geometry>
			<origin rpy="0 0 0" xyz="0 0 0"/>
   		</visual>
		<xacro:default_inertial mass="0.0001"/>
 	</link>

	<gazebo reference="base_footprint">
		<material>Gazebo/Green</material>
		<turnGravityOff>false</turnGravityOff>
	</gazebo>

	<joint name="base_footprint_joint" type="fixed">
		<origin xyz="0 0 0" rpy="0 0 0"/>
		<parent link="base_footprint" />
		<child link="base_link" />
	</joint>
-->
  <!--base link-->
  <link name="base_link">
    <visual>
      <geometry>
        <box size="0.01 0.01 0.01"/>
      </geometry>
      <origin rpy="0 0 0" xyz="0 0 0"/>
      <material name="blue">
        <color rgba="0 0 1 0.7"/>
      </material>
    </visual>
    <collision>
      <geometry>
        <box size="0.01 0.01 0.01"/>
      </geometry>
    </collision>
    <inertial>
      <mass value="1"/>
      <inertia ixx="1.0" ixy="0.0" ixz="0.0" iyy="1.0" iyz="0.0" izz="1.0"/>
    </inertial>
  </link>
  <!--main_body-->
  <link name="main_body">
    <visual>
      <geometry>
        <box size="0.8535 0.81 0.96"/>
      </geometry>
      <origin rpy="0 0 0" xyz="0 0 0"/>
      <material name="blue">
        <color rgba="0 0 1 0.7"/>
      </material>
    </visual>
    <collision>
      <geometry>
        <box size="0.8535 0.81 0.96"/>
      </geometry>
    </collision>
    <inertial>
      <mass value="100"/>
      <inertia ixx="1.0" ixy="0.0" ixz="0.0" iyy="1.0" iyz="0.0" izz="1.0"/>
    </inertial>
  </link>
  <!--left lift-->
  <link name="left_lift">
    <visual>
      <geometry>
        <box size="1.313 0.15 0.1"/>
      </geometry>
      <origin rpy="0 0 0" xyz="0 0 0"/>
      <material name="red">
        <color rgba="1 0 0 0.7"/>
      </material>
    </visual>
    <collision>
      <geometry>
        <box size="1.313 0.15 0.1"/>
      </geometry>
    </collision>
    <inertial>
      <mass value="20"/>
      <inertia ixx="1.0" ixy="0.0" ixz="0.0" iyy="1.0" iyz="0.0" izz="1.0"/>
    </inertial>
  </link>
  <!--right lift-->
  <link name="right_lift">
    <visual>
      <geometry>
        <box size="1.313 0.15 0.1"/>
      </geometry>
      <origin rpy="0 0 0" xyz="0 0 0"/>
      <material name="red">
        <color rgba="1 0 0 0.7"/>
      </material>
    </visual>
    <collision>
      <geometry>
        <box size="1.313 0.15 0.1"/>
      </geometry>
    </collision>
    <inertial>
      <mass value="20"/>
      <inertia ixx="1.0" ixy="0.0" ixz="0.0" iyy="1.0" iyz="0.0" izz="1.0"/>
    </inertial>
  </link>
  <link name="laser">
    <visual>
      <geometry>
        <box size="0.156 0.155 0.185"/>
      </geometry>
      <origin rpy="0 0 0" xyz="0 0 0"/>
      <material name="blue_">
        <color rgba="0 0 1 1"/>
      </material>
    </visual>
    <collision>
      <geometry>
        <box size="0.156 0.155 0.185"/>
      </geometry>
    </collision>
    <inertial>
      <mass value="20"/>
      <inertia ixx="1.0" ixy="0.0" ixz="0.0" iyy="1.0" iyz="0.0" izz="1.0"/>
    </inertial>
  </link>
  <link name="front_caster">
    <visual>
      <geometry>
        <cylinder length="0.3" radius="0.05"/>
      </geometry>
      <!-- <origin rpy="0 1.5 0" xyz="0.1 0.1 0"/> -->
      <origin rpy="0 0 0" xyz="0 0 0"/>
      <material name="green">
        <color rgba="0 1 0 1"/>
      </material>
    </visual>
    <collision>
      <geometry>
        <cylinder length="0.3" radius="0.05"/>
      </geometry>
    </collision>
    <inertial>
      <mass value="10"/>
      <inertia ixx="1.0" ixy="0.0" ixz="0.0" iyy="1.0" iyz="0.0" izz="1.0"/>
    </inertial>
  </link>
  <link name="front_wheel">
    <visual>
      <geometry>
        <cylinder length="0.1" radius="0.125"/>
      </geometry>
      <!-- <origin rpy="0 1.5 0" xyz="0.1 0.1 0"/> -->
      <origin rpy="0 0 0" xyz="0 0 0"/>
      <material name="black">
        <color rgba="0 0 0 1"/>
      </material>
    </visual>
    <collision>
      <geometry>
        <cylinder length="0.1" radius="0.125"/>
      </geometry>
    </collision>
    <inertial>
      <mass value="10"/>
      <inertia ixx="1.0" ixy="0.0" ixz="0.0" iyy="1.0" iyz="0.0" izz="1.0"/>
    </inertial>
  </link>
  <link name="left_caster">
    <visual>
      <geometry>
        <cylinder length="0.2" radius="0.03"/>
      </geometry>
      <!-- <origin rpy="0 1.5 0" xyz="0.1 0.1 0"/> -->
      <origin rpy="0 0 0" xyz="0 0 0"/>
      <material name="green">
        <color rgba="0 1 0 1"/>
      </material>
    </visual>
    <collision>
      <geometry>
        <cylinder length="0.2" radius="0.03"/>
      </geometry>
    </collision>
    <inertial>
      <mass value="10"/>
      <inertia ixx="1.0" ixy="0.0" ixz="0.0" iyy="1.0" iyz="0.0" izz="1.0"/>
    </inertial>
  </link>
  <link name="left_caster_wheel">
    <visual>
      <geometry>
        <cylinder length="0.1" radius="0.065"/>
      </geometry>
      <!-- <origin rpy="0 1.5 0" xyz="0.1 0.1 0"/> -->
      <origin rpy="0 0 0" xyz="0 0 0"/>
      <material name="black">
        <color rgba="0 0 0 1"/>
      </material>
    </visual>
    <collision>
      <geometry>
        <cylinder length="0.1" radius="0.065"/>
      </geometry>
    </collision>
    <inertial>
      <mass value="10"/>
      <inertia ixx="1.0" ixy="0.0" ixz="0.0" iyy="1.0" iyz="0.0" izz="1.0"/>
    </inertial>
  </link>
  <link name="right_caster">
    <visual>
      <geometry>
        <cylinder length="0.2" radius="0.03"/>
      </geometry>
      <!-- <origin rpy="0 1.5 0" xyz="0.1 0.1 0"/> -->
      <origin rpy="0 0 0" xyz="0 0 0"/>
      <material name="green">
        <color rgba="0 1 0 1"/>
      </material>
    </visual>
    <collision>
      <geometry>
        <cylinder length="0.2" radius="0.03"/>
      </geometry>
    </collision>
    <inertial>
      <mass value="10"/>
      <inertia ixx="1.0" ixy="0.0" ixz="0.0" iyy="1.0" iyz="0.0" izz="1.0"/>
    </inertial>
  </link>
  <link name="right_caster_wheel">
    <visual>
      <geometry>
        <cylinder length="0.1" radius="0.065"/>
      </geometry>
      <!-- <origin rpy="0 1.5 0" xyz="0.1 0.1 0"/> -->
      <origin rpy="0 0 0" xyz="0 0 0"/>
      <material name="black">
        <color rgba="0 0 0 1"/>
      </material>
    </visual>
    <collision>
      <geometry>
        <cylinder length="0.1" radius="0.065"/>
      </geometry>
    </collision>
    <inertial>
      <mass value="10"/>
      <inertia ixx="1.0" ixy="0.0" ixz="0.0" iyy="1.0" iyz="0.0" izz="1.0"/>
    </inertial>
  </link>
  <link name="left_lift_wheel">
    <visual>
      <geometry>
        <cylinder length="0.1" radius="0.04"/>
      </geometry>
      <!-- <origin rpy="0 1.5 0" xyz="0.1 0.1 0"/> -->
      <origin rpy="0 0 0" xyz="0 0 0"/>
      <material name="black">
        <color rgba="0 0 0 1"/>
      </material>
    </visual>
    <collision>
      <geometry>
        <cylinder length="0.1" radius="0.04"/>
      </geometry>
    </collision>
    <inertial>
      <mass value="10"/>
      <inertia ixx="1.0" ixy="0.0" ixz="0.0" iyy="1.0" iyz="0.0" izz="1.0"/>
    </inertial>
  </link>
  <link name="right_lift_wheel">
    <visual>
      <geometry>
        <cylinder length="0.1" radius="0.04"/>
      </geometry>
      <!-- <origin rpy="0 1.5 0" xyz="0.1 0.1 0"/> -->
      <origin rpy="0 0 0" xyz="0 0 0"/>
      <material name="black">
        <color rgba="0 0 0 1"/>
      </material>
    </visual>
    <collision>
      <geometry>
        <cylinder length="0.1" radius="0.04"/>
      </geometry>
    </collision>
    <inertial>
      <mass value="10"/>
      <inertia ixx="1.0" ixy="0.0" ixz="0.0" iyy="1.0" iyz="0.0" izz="1.0"/>
    </inertial>
  </link>
  <!--        <joint name="base_footprint_base_link" type="fixed">
                <origin xyz="0 0 0" rpy="0 0 0"/>
                <parent link="base_footprint" />
                <child link="base_link" />
        </joint>
-->
  <!-- add 0.4 -->
  <joint name="base_link_main_body" type="fixed">
    <origin rpy="0 0 0" xyz="1.613 0 0.4"/>
    <parent link="base_link"/>
    <child link="main_body"/>
  </joint>
  <joint name="base_link_laser_link" type="fixed">
    <origin rpy="0 0 0" xyz="2.117 0 0"/>
    <!-- -0.4 -->
    <parent link="base_link"/>
    <child link="laser"/>
  </joint>
  <joint name="base_link_left_lift" type="fixed">
    <origin rpy="0 0 0" xyz="0.53 0.275 -0.03"/>
    <parent link="base_link"/>
    <child link="left_lift"/>
  </joint>
  <joint name="base_link_right_lift" type="fixed">
    <origin rpy="0 0 0" xyz="0.53 -0.275 -0.03"/>
    <parent link="base_link"/>
    <child link="right_lift"/>
  </joint>
  <joint name="base_link_front_caster" type="continuous">
    <parent link="base_link"/>
    <child link="front_caster"/>
    <origin rpy="0 0 0" xyz="1.772 0 0.07"/>
    <axis xyz="0 0 1"/>
  </joint>
  <joint name="front_caster_front_wheel" type="continuous">
    <axis xyz="0 0 1"/>
    <!--	<anchor xyz="0 0 0" />
   		<limit effort="100" velocity="100" />
   	-->
    <parent link="front_caster"/>
    <child link="front_wheel"/>
    <origin rpy="-1.5707 0 0" xyz="0 0 -0.15"/>
  </joint>
  <joint name="base_link_left_caster" type="continuous">
    <parent link="base_link"/>
    <axis xyz="0 0 1"/>
    <child link="left_caster"/>
    <origin rpy="0 0 0" xyz="1.518 0.275 -0.04"/>
  </joint>
  <joint name="left_caster_left_caster_wheel" type="continuous">
    <parent link="left_caster"/>
    <axis xyz="0 0 1"/>
    <child link="left_caster_wheel"/>
    <origin rpy="-1.5707 0 0" xyz="0 0 -0.1"/>
  </joint>
  <joint name="base_link_right_caster" type="continuous">
    <parent link="base_link"/>
    <axis xyz="0 0 1"/>
    <child link="right_caster"/>
    <origin rpy="0 0 0" xyz="1.518 -0.275 -0.04"/>
  </joint>
  <joint name="right_caster_right_caster_wheel" type="continuous">
    <parent link="right_caster"/>
    <axis xyz="0 0 1"/>
    <child link="right_caster_wheel"/>
    <origin rpy="-1.5707 0 0" xyz="0 0 -0.1"/>
  </joint>
  <joint name="left_lift_left_lift_wheel" type="continuous">
    <parent link="left_lift"/>
    <axis xyz="0 0 1"/>
    <child link="left_lift_wheel"/>
    <origin rpy="-1.5707 0 0" xyz="-0.522 0 -0.135"/>
  </joint>
  <joint name="right_lift_right_lift_wheel" type="continuous">
    <parent link="right_lift"/>
    <axis xyz="0 0 1"/>
    <child link="right_lift_wheel"/>
    <origin rpy="-1.5707 0 0" xyz="-0.522 0 -0.135"/>
  </joint>
  <!--
	<gazebo>
		<plugin	name="differential_drive_controller"
			filename="libgazebo_ros_diff_drive.so">
		//	<leftJoint>base_link_left_caster</leftJoint>
		//	<rightJoint>base_link_right_caster</rightJoint>
			<leftJoint>left_lift_left_lift_wheel</leftJoint>
			<rightJoint>right_lift_right_lift_wheel</rightJoint>
			<commandTopic>cmd_vel</commandTopic>
			<odometryTopic>odom</odometryTopic>
			<robotBaseFrame>base_link</robotBaseFrame>
			<wheelSeparation>0.55</wheelSeparation>
			<wheelDiameter>0.04</wheelDiameter>
			<publishWheelJointState>true</publishWheelJointState>
		</plugin>
	</gazebo>
-->
</robot>
