<?xml version="1.0"?>

<robot 
	xmlns:xacro="http://www.ros.org/wiki/xacro" 
 	xmlns:sensor="http://playerstage.sourceforge.net/gazebo/xmlschema/#sensor"
    	xmlns:controller="http://playerstage.sourceforge.net/gazebo/xmlschema/#controller"
    	xmlns:interface="http://playerstage.sourceforge.net/gazebo/xmlschema/#interface"
	name="robot_seldat">

	<xacro:property name="length_front_caster" value="0.3" />
	<xacro:property name="radius_front_caster" value="0.05" /> <!--0.15-->

	<xacro:property name="length_front_wheel" value="0.1" />
        <xacro:property name="radius_front_wheel" value="0.125" />

        <xacro:property name="length_mid_caster" value="0.2" />
        <xacro:property name="radius_mid_caster" value="0.03" /> <!--0.09-->
        
	<xacro:property name="length_caster_wheel" value="0.1" />
        <xacro:property name="radius_caster_wheel" value="0.065" />
        
	<xacro:property name="length_lift_wheel" value="0.2" />
        <xacro:property name="radius_lift_wheel" value="0.04" />

	<xacro:macro name="default_inertial" params="mass">
               <inertial>
                       <mass value="${mass}" />
                       <inertia ixx="1.0" ixy="0.0" ixz="0.0"
                                iyy="1.0" iyz="0.0"
                                izz="1.0" />
               </inertial>
	</xacro:macro>
	<!--base footprint-->
<!--	<link name="base_footprint">
   		<visual>
			<geometry>
      				<box size="0.001 0.001 0.001"/>
     			</geometry>
			<origin rpy="0 0 0" xyz="0 0 0"/>
   		</visual>
		<xacro:default_inertial mass="0.0001"/>
 	</link>

	<gazebo reference="base_footprint">
		<material>Gazebo/Green</material>
		<turnGravityOff>false</turnGravityOff>
	</gazebo>

	<joint name="base_footprint_joint" type="fixed">
		<origin xyz="0 0 0" rpy="0 0 0"/>
		<parent link="base_footprint" />
		<child link="base_link" />
	</joint>
-->
	
	<!--base link-->
	<link name="base_link">
   		<visual>
			<geometry>
      				<box size="0.01 0.01 0.01"/>
     			</geometry>
			<origin rpy="0 0 0" xyz="0 0 0"/>
			<material name="blue">
				<color rgba="0 0 1 0.7"/>
			</material>
   		</visual>
		<collision>
			<geometry>
       				<box size="0.01 0.01 0.01"/>
			</geometry>
		</collision>
		<xacro:default_inertial mass="1"/>
 	</link>
	
	<!--main_body-->
	<link name ="main_body">
		<visual>
			<geometry>
                                <box size="0.75 1.02 0.83"/>
                        </geometry>
                        <origin rpy="0 0 0" xyz="0 0 0"/>
                        <material name="blue">
                                <color rgba="0 0 0.5 1"/>
                        </material>
                </visual>
                <collision>
                        <geometry>
                                <box size="0.75 1.02 0.83"/>
                        </geometry>
                </collision>
                <xacro:default_inertial mass="100"/>
        </link>

        <!--middle frame-->
        <link name ="middle_frame">
                <visual>
                        <geometry>
                                <box size="0.2 1.505 0.1"/>
                        </geometry>
                        <origin rpy="0 0 0" xyz="0 0 0"/>
                        <material name="blue">
                                <color rgba="0 0 1 0.7"/>
                        </material>
                </visual>
                <collision>
                        <geometry>
                                <box size="0.2 1.505 0.1"/>
                        </geometry>
                </collision>
                <xacro:default_inertial mass="20"/>
        </link>

        <!--left_frame-->
        <link name ="left_frame">
                <visual>
                        <geometry>
                                <box size="0.60 0.2 0.1"/>
                        </geometry>
                        <origin rpy="0 0 0" xyz="0 0 0"/>
                        <material name="blue">
                                <color rgba="0 0 1 0.7"/>
                        </material>
                </visual>
                <collision>
                        <geometry>
                                <box size="0.51 0.2 0.1"/>
                        </geometry>
                </collision>
                <xacro:default_inertial mass="20"/>
        </link>

        <!--right_frame-->
        <link name ="right_frame">
                <visual>
                        <geometry>
                                <box size="0.60 0.2 0.1"/>
                        </geometry>
                        <origin rpy="0 0 0" xyz="0 0 0"/>
                        <material name="blue">
                                <color rgba="0 0 1 0.7"/>
                        </material>
                </visual>
                <collision>
                        <geometry>
                                <box size="0.51 0.2 0.1"/>
                        </geometry>
                </collision>
                <xacro:default_inertial mass="20"/>
        </link>

	<!--left lift-->
        <link name="left_lift">
                <visual>
                        <geometry>
                                <box size="1.0 0.15 0.05"/>
                        </geometry>
                        <origin rpy="0 0 0" xyz="0 0 0"/>
                        <material name="red">
                                <color rgba="0 0 0 1"/>
                        </material>
                </visual>
                <collision>
                        <geometry>
                                <box size="1.0 0.15 0.05"/>
                        </geometry>
                </collision>
                <xacro:default_inertial mass="20"/>
        </link>
	<!--right lift-->
        <link name="right_lift">
                <visual>
                        <geometry>
                                <box size="1.0 0.15 0.05"/>
                        </geometry>
                        <origin rpy="0 0 0" xyz="0 0 0"/>
                        <material name="red">
                                <color rgba="0 0 0 1"/>
                        </material>
                </visual>
                <collision>
                        <geometry>
                                <box size="1.0 0.15 0.05"/>
                        </geometry>
                </collision>
                <xacro:default_inertial mass="20"/>
        </link>

        <link name="laser">
                <visual>
                        <geometry>
                                <box size="0.156 0.155 0.185"/>
                        </geometry>
                        <origin rpy="0 0 0" xyz="0 0 0"/>
                        <material name="blue_">
                                <color rgba="0 0 1 1"/>
                        </material>
                </visual>
                <collision>
                        <geometry>
                                <box size="0.156 0.155 0.185"/>
                        </geometry>
                </collision>
                <xacro:default_inertial mass="20"/>
        </link>

 	<link name="front_caster">
   		<visual>
     			<geometry>
       				<cylinder length="${length_front_caster}" radius="${radius_front_caster}"/>
			</geometry>
			<!-- <origin rpy="0 1.5 0" xyz="0.1 0.1 0"/> -->
			<origin rpy="0 0 0" xyz="0 0 0"/>
   			<material name="green">
				<color rgba="0 1 0 1"/>
			</material>
		</visual>
		<collision>
			<geometry>
       				<cylinder length="${length_front_caster}" radius="${radius_front_caster}"/>
			</geometry>
		</collision>
		<xacro:default_inertial mass="10"/>
 	</link>

 	<link name="front_wheel">
   		<visual>
     			<geometry>
       				<cylinder length="${length_front_wheel}" radius="${radius_front_wheel}"/>
     			</geometry>
			<!-- <origin rpy="0 1.5 0" xyz="0.1 0.1 0"/> -->
			<origin rpy="0 0 0" xyz="0 0 0"/>
   			<material name="black">
				<color rgba="0 0 0 1"/>
			</material>
		</visual>
		<collision>
			<geometry>
       				<cylinder length="${length_front_wheel}" radius="${radius_front_wheel}"/>
			</geometry>
		</collision>
		<xacro:default_inertial mass="10"/>
 	</link>

        <link name="left_caster">
                <visual>
                        <geometry>
                                <cylinder length="${length_mid_caster}" radius="${radius_mid_caster}"/>
                        </geometry>
                        <!-- <origin rpy="0 1.5 0" xyz="0.1 0.1 0"/> -->
                        <origin rpy="0 0 0" xyz="0 0 0"/>
                        <material name="green">
                                <color rgba="0 1 0 1"/>
                        </material>
                </visual>
                <collision>
                        <geometry>
                                <cylinder length="${length_mid_caster}" radius="${radius_mid_caster}"/>
                        </geometry>
                </collision>
                <xacro:default_inertial mass="10"/>
        </link>

        <link name="left_caster_wheel">
                <visual>
                        <geometry>
                                <cylinder length="${length_caster_wheel}" radius="${radius_caster_wheel}"/>
                        </geometry>
                        <!-- <origin rpy="0 1.5 0" xyz="0.1 0.1 0"/> -->
                        <origin rpy="0 0 0" xyz="0 0 0"/>
                        <material name="black">
                                <color rgba="0 0 0 1"/>
                        </material>
                </visual>
                <collision>
                        <geometry>
                                <cylinder length="${length_caster_wheel}" radius="${radius_caster_wheel}"/>
                        </geometry>
                </collision>
                <xacro:default_inertial mass="10"/>
        </link>

        <link name="right_caster">
                <visual>
                        <geometry>
                                <cylinder length="${length_mid_caster}" radius="${radius_mid_caster}"/>
                        </geometry>
                        <!-- <origin rpy="0 1.5 0" xyz="0.1 0.1 0"/> -->
                        <origin rpy="0 0 0" xyz="0 0 0"/>
                        <material name="green">
                                <color rgba="0 1 0 1"/>
                        </material>
                </visual>
                <collision>
                        <geometry>
                                <cylinder length="${length_mid_caster}" radius="${radius_mid_caster}"/>
                        </geometry>
                </collision>
                <xacro:default_inertial mass="10"/>
        </link>

        <link name="right_caster_wheel">
                <visual>
                        <geometry>
                                <cylinder length="${length_caster_wheel}" radius="${radius_caster_wheel}"/>
                        </geometry>
                        <!-- <origin rpy="0 1.5 0" xyz="0.1 0.1 0"/> -->
                        <origin rpy="0 0 0" xyz="0 0 0"/>
                        <material name="black">
                                <color rgba="0 0 0 1"/>
                        </material>
                </visual>
                <collision>
                        <geometry>
                                <cylinder length="${length_caster_wheel}" radius="${radius_caster_wheel}"/>
                        </geometry>
                </collision>
                <xacro:default_inertial mass="10"/>
        </link>

        <link name="left_lift_wheel">
                <visual>
                        <geometry>
                                <cylinder length="${length_lift_wheel}" radius="${radius_lift_wheel}"/>
                        </geometry>
                        <!-- <origin rpy="0 1.5 0" xyz="0.1 0.1 0"/> -->
                        <origin rpy="0 0 0" xyz="0 0 0"/>
                        <material name="black">
                                <color rgba="0 0 0 1"/>
                        </material>
                </visual>
                <collision>
                        <geometry>
                                <cylinder length="${length_lift_wheel}" radius="${radius_lift_wheel}"/>
                        </geometry>
                </collision>
                <xacro:default_inertial mass="10"/>
        </link>

        <link name="right_lift_wheel">
                <visual>
                        <geometry>
                                <cylinder length="${length_lift_wheel}" radius="${radius_lift_wheel}"/>
                        </geometry>
                        <!-- <origin rpy="0 1.5 0" xyz="0.1 0.1 0"/> -->
                        <origin rpy="0 0 0" xyz="0 0 0"/>
                        <material name="black">
                                <color rgba="0 0 0 1"/>
                        </material>
                </visual>
                <collision>
                        <geometry>
                                <cylinder length="${length_lift_wheel}" radius="${radius_lift_wheel}"/>
                        </geometry>
                </collision>
                <xacro:default_inertial mass="10"/>
        </link>

<!--        <joint name="base_footprint_base_link" type="fixed">
                <origin xyz="0 0 0" rpy="0 0 0"/>
                <parent link="base_footprint" />
                <child link="base_link" />
        </joint>
-->
	<!-- add 0.4 -->
	<joint name="base_link_main_body" type="fixed">
                <origin xyz="0.875 0 0.445" rpy="0 0 0"/>
                <parent link="base_link" />
                <child link="main_body" />
        </joint>

    	<joint name="main_body_middle_frame" type="fixed">
                <origin xyz="-0.275 0 -0.365" rpy="0 0 0"/> <!-- -0.4 -->
                <parent link="main_body"/>
                <child link="middle_frame"/>
	</joint>

    	<joint name="middle_frame_left_frame" type="fixed">
                <origin xyz="-0.4 0.6525 0" rpy="0 0 0"/> <!-- -0.4 -->
                <parent link="middle_frame"/>
                <child link="left_frame"/>
	</joint>

    	<joint name="middle_frame_right_frame" type="fixed">
                <origin xyz="-0.4 -0.6525 0" rpy="0 0 0"/> <!-- -0.4 -->
                <parent link="middle_frame"/>
                <child link="right_frame"/>
	</joint>

    	<joint name="base_link_laser_link" type="fixed">
                <origin xyz="1.335 0 0.165" rpy="0 0 0"/> <!-- -0.4 -->
                <parent link="base_link"/>
                <child link="laser"/>
	</joint>

        <joint name="main_body_left_lift" type="fixed">
                <origin xyz="-0.875 0.36 -0.37" rpy="0 0 0"/>
                <parent link="main_body"/>
                <child link="left_lift"/>
        </joint>

        <joint name="main_body_right_lift" type="fixed">
                <origin xyz="-0.875 -0.36 -0.37" rpy="0 0 0"/>
                <parent link="main_body"/>
                <child link="right_lift"/>
        </joint>

 	<joint name="base_link_front_caster" type="continuous">
   		<parent link="base_link"/>
   		<child link="front_caster"/>
   		<origin rpy="0 0 0" xyz="1.0 0 0.275"/>
   		<axis xyz="0 0 1" />
 	</joint>

 	<joint name="front_caster_front_wheel" type="continuous">
   		<axis xyz="0 0 1" />
   	<!--	<anchor xyz="0 0 0" />
   		<limit effort="100" velocity="100" />
   	-->	<parent link="front_caster"/>
   		<child link="front_wheel"/>
  		<origin rpy="-1.5707 0 0" xyz="0 0 -0.15"/>
	</joint>

        <joint name="base_link_left_caster" type="continuous">
                <parent link="base_link"/>
                <axis xyz="0 0 1" />
                <child link="left_caster"/>
                <origin rpy="0 0 0" xyz="0.929 0.372 0.165"/>
        </joint>

 	<joint name="left_caster_left_caster_wheel" type="continuous">
   		<parent link="left_caster"/>
   		<axis xyz="0 0 1" />
   		<child link="left_caster_wheel"/>
   		<origin rpy="-1.5707 0 0" xyz="0 0 -0.1"/>
 	</joint>

        <joint name="base_link_right_caster" type="continuous">
                <parent link="base_link"/>
                <axis xyz="0 0 1" />
                <child link="right_caster"/>
                <origin rpy="0 0 0" xyz="0.929 -0.372 0.165"/>
        </joint>

        <joint name="right_caster_right_caster_wheel" type="continuous">
                <parent link="right_caster"/>
                <axis xyz="0 0 1" />
                <child link="right_caster_wheel"/>
                <origin rpy="-1.5707 0 0" xyz="0 0 -0.1"/>
        </joint>

 	<joint name="left_frame_left_lift_wheel" type="continuous">
   		<parent link="left_frame"/>
   		<axis xyz="0 0 1" />
   		<child link="left_lift_wheel"/>
   		<origin rpy="-1.5707 0 0" xyz="-0.2 0 -0.04"/>
 	</joint>

        <joint name="right_frame_right_lift_wheel" type="continuous">
                <parent link="right_frame"/>
                <axis xyz="0 0 1" />
                <child link="right_lift_wheel"/>
                <origin rpy="-1.5707 0 0" xyz="-0.2 0 -0.04"/>
        </joint>       
<!--
	<gazebo>
		<plugin	name="differential_drive_controller"
			filename="libgazebo_ros_diff_drive.so">
		//	<leftJoint>base_link_left_caster</leftJoint>
		//	<rightJoint>base_link_right_caster</rightJoint>
			<leftJoint>left_lift_left_lift_wheel</leftJoint>
			<rightJoint>right_lift_right_lift_wheel</rightJoint>
			<commandTopic>cmd_vel</commandTopic>
			<odometryTopic>odom</odometryTopic>
			<robotBaseFrame>base_link</robotBaseFrame>
			<wheelSeparation>0.55</wheelSeparation>
			<wheelDiameter>0.04</wheelDiameter>
			<publishWheelJointState>true</publishWheelJointState>
		</plugin>
	</gazebo>
-->
</robot>

